Workbook

Sheet B73 and Mo17
A1: Table S3. Differentially expressed genes in response to R. padi feeding in B73 and Mo17
A2: B73 0 h: No aphid treatment on B73
A3: B73 6 h: Aphid treatment on B73 for 6 h
A4: B73 24 h: Aphid treatment on B73 for 24 h
A5: Mo17 0 h: No aphid treatment on Mo17
A6: Mo17 6 h: Aphid treatment on Mo17 for 6 h
A7: Mo17 24 h: Aphid treatment on Mo17 for 24 h
A8: NA: no annotation.
A9: BD: numerator or denominator is below of detection
A10: gene | B10: GO term | C10: Description | D10: sample_1 | E10: sample_2 | F10: value_1 | G10: value_2 | H10: log2(fold_change)
A11: GRMZM2G045031 | B11: NA | C11: uncharacterized protein LOC100278663 | D11: Mo17 0 h | E11: Mo17 6 h | F11: 0.138254 | G11: 11.495 | H11: 6.37754
A12: GRMZM2G028640 | B12: NA | C12: enzyme of the cupin superfamily | D12: B73 0 h | E12: B73 24 h | F12: 0.626461 | G12: 38.7026 | H12: 5.94906
A13: GRMZM5G891371 | B13: NA | C13: subtilase family protein | D13: B73 0 h | E13: B73 24 h | F13: 0.191896 | G13: 7.97984 | H13: 5.37797
A14: GRMZM2G468111 | B14: NA | C14: uncharacterized protein LOC100277849 | D14: Mo17 0 h | E14: Mo17 6 h | F14: 1.70723 | G14: 62.0608 | H14: 5.18395
A15: AC208221.3_FG002 | B15: GO:0005576GO:0004867 | C15: NA | D15: B73 0 h | E15: B73 24 h | F15: 1.01293 | G15: 35.8602 | H15: 5.14578
A16: GRMZM2G133988 | B16: GO:0008152 | C16: 3-isopropylmalate dehydratase-like | D16: Mo17 0 h | E16: Mo17 6 h | F16: 1.19113 | G16: 41.422 | H16: 5.11999
A17: GRMZM2G474039 | B17: NA | C17: hypothetical protein SORBIDRAFT_06g030720 | D17: B73 0 h | E17: B73 6 h | F17: 0.451313 | G17: 15.3552 | H17: 5.08845
A18: GRMZM2G010044 | B18: GO:0008652GO:0016836GO:0051539 | C18: 3-isopropylmalate dehydratase | D18: Mo17 0 h | E18: Mo17 6 h | F18: 6.3386 | G18: 201.729 | H18: 4.99211
A19: GRMZM5G891371 | B19: NA | C19: subtilase family protein | D19: B73 0 h | E19: B73 6 h | F19: 0.191896 | G19: 5.83183 | H19: 4.92556
A20: GRMZM2G028640 | B20: NA | C20: enzyme of the cupin superfamily | D20: B73 0 h | E20: B73 6 h | F20: 0.626461 | G20: 12.7577 | H20: 4.348
A21: GRMZM2G117706 | B21: GO:0020037GO:0005576GO:0004601GO:0006979GO:0009055 | C21: bacterial-induced peroxidase precursor | D21: Mo17 0 h | E21: Mo17 6 h | F21: 0.404387 | G21: 8.20211 | H21: 4.34219
A22: AC208221.3_FG002 | B22: GO:0005576GO:0004867 | C22: NA | D22: B73 0 h | E22: B73 6 h | F22: 1.01293 | G22: 20.1457 | H22: 4.31387
... A466: GRMZM2G147716 | B466: GO:0003700GO:0006355GO:0005634GO:0043565 | C466: mads-domain transcription factor | D466: Mo17 0 h | E466: Mo17 6 h | F466: 0.336458 | G466: 0.932634 | H466: 1.47089
A467: GRMZM2G127336 | B467: GO:0016829GO:0000287GO:0008152 | C467: #NAME? | D467: Mo17 0 h | E467: Mo17 24 h | F467: 0.500957 | G467: 1.38585 | H467: 1.46801
A468: GRMZM2G024561 | B468: NA | C468: glucan endo- -beta-glucosidase 4 precursor | D468: B73 0 h | E468: B73 24 h | F468: 1.15962 | G468: 3.20666 | H468: 1.46742
A469: GRMZM2G478430 | B469: NA | C469: NA | D469: Mo17 0 h | E469: Mo17 6 h | F469: 0.686541 | G469: 1.8973 | H469: 1.46653
A470: GRMZM2G010321 | B470: GO:0005960GO:0006546 | C470: glycine decarboxylase complex h-protein | D470: Mo17 0 h | E470: Mo17 24 h | F470: 1.29216 | G470: 3.57035 | H470: 1.46628
A471: GRMZM2G436448 | B471: GO:0004674GO:0006468GO:0004713GO:0005524 | C471: rust resistance kinase lr10 | D471: Mo17 0 h | E471: Mo17 24 h | F471: 2.64149 | G471: 7.29302 | H471: 1.46517
A472: GRMZM2G077436 | B472: GO:0003700GO:0006355GO:0006352GO:0016987 | C472: rna polymerase sigma factor rpod-like | D472: B73 0 h | E472: B73 6 h | F472: 3.65501 | G472: 10.0908 | H472: 1.4651
A473: AC233888.1_FG001 | B473: NA | C473: NA | D473: B73 0 h | E473: B73 6 h | F473: 2.29972 | G473: 6.34071 | H473: 1.46319
A474: GRMZM2G118104 | B474: GO:0016787 | C474: pre-mrna cleavage factor 25kd | D474: Mo17 0 h | E474: Mo17 6 h | F474: 2.68239 | G474: 7.38878 | H474: 1.46182
A475: GRMZM2G167689 | B475: NA | C475: NA | D475: Mo17 0 h | E475: Mo17 6 h | F475: 2.4474 | G475: 6.72365 | H475: 1.458
A476: GRMZM2G044077 | B476: GO:0003700GO:0006355 | C476: ap2 erf domain-containing transcription factor | D476: Mo17 0 h | E476: Mo17 6 h | F476: 0.374954 | G476: 1.02996 | H476: 1.4578
A477: GRMZM2G349839 | B477: NA | C477: gda1 cd39 family expressed | D477: B73 0 h | E477: B73 6 h | F477: 2.23847 | G477: 6.1476 | H477: 1.45751
A478: GRMZM2G088819 | B478: GO:0005509 | C478: calcium-binding protein cml42 | D478: Mo17 0 h | E478: Mo17 24 h | F478: 2.07739 | G478: 5.70481 | H478: 1.4574
A479: AC203909.3_FG003 | B479: GO:0019882GO:0050660GO:0016020GO:0006955GO:0009055GO:0016491 | C479: NA | D479: Mo17 0 h | E479: Mo17 6 h | F479: 0.683655 | G479: 1.87549 | H479: 1.45593
... A893: GRMZM2G068179 | B893: NA | C893: leucine carboxyl methyltransferase | D893: B73 0 h | E893: B73 24 h | F893: 6.33415 | G893: 14.0552 | H893: 1.14988
A894: GRMZM2G137864 | B894: GO:0005840GO:0005634GO:0003677GO:0003735GO:0006355GO:0050825GO:0042309GO:0050826GO:0006412GO:0004879 | C894: 0 | D894: B73 0 h | E894: B73 24 h | F894: 331.985 | G894: 736.31 | H894: 1.14919
A895: GRMZM2G132995 | B895: GO:0015297GO:0016020GO:0006855GO:0015238 | C895: transparent testa 12 protein | D895: Mo17 0 h | E895: Mo17 6 h | F895: 0.454705 | G895: 1.00839 | H895: 1.14905
A896: GRMZM2G048194 | B896: GO:0016998 | C896: erwinia induced protein 1 | D896: Mo17 0 h | E896: Mo17 6 h | F896: 0.712826 | G896: 1.57954 | H896: 1.14788
...

Sheet B73 6 h
A1: Table S3. Differentially expressed genes in response to R. padi feeding in B73 and Mo17 | M1: log2(fold_change)
A2: B73 0 h:No aphid treatment on B73,B73 6 h: Aphid treatment B73 for 6 h; NA：no annotation.BD: numerator or denominator is below of detection | L2: GRMZM2G055698 | M2: -1.35054
A3: gene | B3: GO term | C3: Description | D3: sample_1 | E3: sample_2 | F3: value_1 | G3: value_2 | H3: log2(fold_change) | L3: GRMZM2G030567 | M3: -1.43793
A4: GRMZM2G055698 | B4: GO:0016021 | C4: membrane protein | D4: B73 0 h | E4: B73 6 h | F4: 12.1189 | G4: 4.75237 | H4: -1.35054 | I4: 1 | L4: GRMZM2G092813 | M4: 1.14393
A5: GRMZM2G030567 | B5: NA | C5: hypothetical protein SORBIDRAFT_01g049390 | D5: B73 0 h | E5: B73 6 h | F5: 3.27985 | G5: 1.21058 | H5: -1.43793 | I5: 1 | L5: GRMZM2G018579 | M5: -1.04583
A6: GRMZM2G092813 | B6: GO:0003824GO:0008152 | C6: acyl:coa ligase acetate-coa synthetase-like protein | D6: B73 0 h | E6: B73 6 h | F6: 6.53338 | G6: 14.4376 | H6: 1.14393 | I6: 1 | L6: GRMZM2G132367 | M6: -1.04277
A7: GRMZM2G018579 | B7: NA | C7: protein | D7: B73 0 h | E7: B73 6 h | F7: 21.8294 | G7: 10.5734 | H7: -1.04583 | I7: 1 | L7: GRMZM2G075712 | M7: -1.02879
A8: GRMZM2G132367 | B8: GO:0003700GO:0006355GO:0005634GO:0043565 | C8: homeodomain-leucine zipper transcription factor ipi-1 | D8: B73 0 h | E8: B73 6 h | F8: 5.47857 | G8: 2.65926 | H8: -1.04277 | I8: 1 | L8: GRMZM2G331638 | M8: -1.85375
A9: GRMZM2G075712 | B9: NA | C9: uncharacterized protein LOC100303821 | D9: B73 0 h | E9: B73 6 h | F9: 22.5554 | G9: 11.0549 | H9: -1.02879 | I9: 1 | L9: GRMZM2G180452 | M9: -1.05159
A10: GRMZM2G331638 | B10: NA | C10: dopamine beta-monooxygenase | D10: B73 0 h | E10: B73 6 h | F10: 1.20792 | G10: 0.334199 | H10: -1.85375 | I10: 1 | L10: GRMZM2G001079 | M10: -1.00852
A11: GRMZM2G180452 | B11: GO:0005634GO:0045449GO:0030528 | C11: helix-loop-helix dna-binding domain containing expressed | D11: B73 0 h | E11: B73 6 h | F11: 1.21952 | G11: 0.588337 | H11: -1.05159 | I11: 1 | L11: AC208201.3_FG003 | M11: -1.84622
A12: GRMZM2G001079 | B12: GO:0016020GO:0015018GO:0050825GO:0042309GO:0050826 | C12: glycosyl transferase | D12: B73 0 h | E12: B73 6 h | F12: 2.36128 | G12: 1.17368 | H12: -1.00852 | I12: 1 | L12: GRMZM2G112538 | M12: 1.07263
A13: AC208201.3_FG003 | B13: NA | C13: NA | D13: B73 0 h | E13: B73 6 h | F13: 3.99423 | G13: 1.11087 | H13: -1.84622 | I13: 1 | L13: GRMZM2G318652 | M13: -1.23946
A14: GRMZM2G112538 | B14: GO:0006952GO:0009607 | C14: pathogenesis-related protein 1 | D14: B73 0 h | E14: B73 6 h | F14: 13.4866 | G14: 28.3658 | H14: 1.07263 | I14: 1 | L14: GRMZM2G107597 | M14: -1.09593
A15: GRMZM2G318652 | B15: GO:0050825GO:0042309GO:0050826 | C15: sigma factor binding protein | D15: B73 0 h | E15: B73 6 h | F15: 8.20993 | G15: 3.47717 | H15: -1.23946 | I15: 1 | L15: GRMZM2G038153 | M15: 1.55366
... A24: GRMZM5G846082 | B24: NA | C24: NA | D24: B73 0 h | E24: B73 6 h | F24: 14.8834 | G24: 30.1352 | H24: 1.01774 | I24: 1 | L24: GRMZM2G024927 | M24: 1.10414
A25: GRMZM5G855014 | B25: NA | C25: unknown | D25: B73 0 h | E25: B73 6 h | F25: 0 | G25: 1.36839 | H25: BD | I25: BD | L25: GRMZM2G037265 | M25: -1.22417
A26: GRMZM2G428216 | B26: NA | C26: uncharacterized protein LOC100276732 | D26: B73 0 h | E26: B73 6 h | F26: 983.799 | G26: 491.038 | H26: -1.00253 | I26: 1 | L26: GRMZM2G050177 | M26: -1.15518
A27: GRMZM2G024927 | B27: NA | C27: uncharacterized protein LOC100383747 | D27: B73 0 h | E27: B73 6 h | F27: 0.630867 | G27: 1.35618 | H27: 1.10414 | I27: 1 | L27: GRMZM2G309731 | M27: -1.15369
A28: GRMZM2G037265 | B28: NA | C28: alkaline alpha-galactosidase seed imbibition protein | D28: B73 0 h | E28: B73 6 h | F28: 71.5048 | G28: 30.6073 | H28: -1.22417 | I28: 1 | L28: GRMZM2G101245 | M28: -1.42351
A29: GRMZM2G050177 | B29: NA | C29: alkaline alpha-galactosidase seed imbibition protein | D29: B73 0 h | E29: B73 6 h | F29: 39.9594 | G29: 17.9422 | H29: -1.15518 | I29: 1 | L29: GRMZM2G401147 | M29: -1.25359
A30: GRMZM2G309731 | B30: GO:0003700GO:0006355 | C30: ethylene-responsive transcription factor | D30: B73 0 h | E30: B73 6 h | F30: 4.70656 | G30: 2.11548 | H30: -1.15369 | I30: 1 | L30: GRMZM2G450498 | M30: -1.59673
A31: GRMZM2G101245 | B31: GO:0004674GO:0006468GO:0004713GO:0005524 | C31: avr9 cf-9 rapidly elicited protein | D31: B73 0 h | E31: B73 6 h | F31: 6.2652 | G31: 2.33569 | H31: -1.42351 | I31: 1 | L31: AC212023.4_FG004 | M31: 1.07164
A32: GRMZM2G401147 | B32: GO:0006334GO:0003677GO:0005634GO:0000786 | C32: histone | D32: B73 0 h | E32: B73 6 h | F32: 22.2803 | G32: 9.34444 | H32: -1.25359 | I32: 1 | L32: GRMZM2G154090 | M32: 2.12919
A33: GRMZM2G450498 | B33: GO:0006520GO:0030170 | C33: o-succinylhomoserine sulfhydrylase | D33: B73 0 h | E33: B73 6 h | F33: 81.4459 | G33: 26.9281 | H33: -1.59673 | I33: 1 | L33: GRMZM5G827939 | M33: 3.42046
A34: AC212023.4_FG004 | B34: GO:0004857GO:0030599 | C34: NA | D34: B73 0 h | E34: B73 6 h | F34: 222.816 | G34: 468.319 | H34: 1.07164 | I34: 1 | L34: GRMZM2G162505 | M34: 2.11153
A35: GRMZM2G154090 | B35: GO:0005315GO:0016021GO:0006817 | C35: phosphate transporter 4 | D35: B73 0 h | E35: B73 6 h | F35: 0.239003 | G35: 1.04557 | H35: 2.12919 | I35: 1 | L35: GRMZM2G081554 | M35: 1.68137
A36: GRMZM5G827939 | B36: NA | C36: -dihydroxy-3-keto-5-methylthiopentene dioxygenase 4 | D36: B73 0 h | E36: B73 6 h | F36: 1.17746 | G36: 12.6069 | H36: 3.42046 | I36: 1 | L36: GRMZM2G138455 | M36: -1.02629
A37: GRMZM2G162505 | B37: GO:0004568GO:0006032 | C37: chitinase 2-like | D37: B73 0 h | E37: B73 6 h | F37: 2.06327 | G37: 8.9164 | H37: 2.11153 | I37: 1 | L37: GRMZM2G171118 | M37: 1.37073
... A44: GRMZM2G149219 | B44: GO:0003700GO:0043565GO:0005634GO:0045449 | C44: dna-binding protein | D44: B73 0 h | E44: B73 6 h | F44: 4.06218 | G44: 0.998357 | H44: -2.02463 | I44: 1 | L44: GRMZM2G004036 | M44: 3.29281
A45: GRMZM2G143142 | B45: NA | C45: NA | D45: B73 0 h | E45: B73 6 h | F45: 0 | G45: 1.47512 | H45: BD | I45: BD | L45: GRMZM2G464393 | M45: -1.08922
A46: GRMZM2G090043 | B46: NA | C46: hypothetical protein | D46: B73 0 h | E46: B73 6 h | F46: 1.79164 | G46: 11.1589 | H46: 2.63884 | I46: 1 | L46: GRMZM2G380789 | M46: 3.85137
A47: GRMZM2G010034 | B47: NA | C47: protein | D47: B73 0 h | E47: B73 6 h | F47: 104.093 | G47: 219.783 | H47: 1.07821 | I47: 1 | L47: GRMZM2G003506 | M47: -1.24304
A48: GRMZM2G004036 | B48: GO:0003824GO:0016564GO:0006808GO:0044237GO:0050662 | C48: isoflavone reductase homolog a622-like | D48: B73 0 h | E48: B73 6 h | F48: 0.473781 | G48: 4.64313 | H48: 3.29281 | I48: 1 | L48: GRMZM2G116902 | M48: 1.94465
A49: GRMZM2G464393 | B49: GO:0005515 | C49: protein binding protein | D49: B73 0 h | E49: B73 6 h | F49: 2.21008 | G49: 1.03877 | H49: -1.08922 | I49: 1 | L49: GRMZM2G321033 | M49: -1.18947
A50: GRMZM2G380789 | B50: GO:0016021 | C50: heptahelical protein 4 | D50: B73 0 h | E50: B73 6 h | F50: 0.0796325 | G50: 1.14939 | H50: 3.85137 | I50: 1 | L50: GRMZM2G377647 | M50: -1.05086
A51: GRMZM2G003506 | B51: NA | C51: membrane protein | D51: B73 0 h | E51: B73 6 h | F51: 1.97347 | G51: 0.833752 | H51: -1.24304 | I51: 1 | L51: GRMZM2G305526 | M51: -4.04282
A52: GRMZM2G116902 | B52: GO:0004601GO:0006979GO:0020037GO:0009055 | C52: peroxidase n-like | D52: B73 0 h | E52: B73 6 h | F52: 0.54042 | G52: 2.08032 | H52: 1.94465 | I52: 1 | L52: GRMZM2G043878 | M52: 2.86101
A53: GRMZM2G321033 | B53: GO:0004497GO:0020037GO:0009055 | C53: cytochrome p450 family expressed | D53: B73 0 h | E53: B73 6 h | F53: 0.889747 | G53: 0.390121 | H53: -1.18947 | I53: 1 | L53: GRMZM2G338037 | M53: 1.9566
A54: GRMZM2G377647 | B54: NA | C54: uncharacterized protein LOC100276586 | D54: B73 0 h | E54: B73 6 h | F54: 2.58959 | G54: 1.24994 | H54: -1.05086 | I54: 1 | L54: GRMZM2G053669 | M54: 1.12979
...

Sheet B73 24 h
A1: Table S3. Differentially expressed genes in response to R. padi feeding in B73 and Mo17 | M1: log2(fold_change)
A2: B73 0 h:No aphid treatment on B73,B73 24 h: Aphid treatment B73 for 24 h; NA：no annotation.BD: numerator or denominator is below of detection | L2: GRMZM2G392863 | M2: 1.1343
A3: gene | B3: GO term | C3: Description | D3: sample_1 | E3: sample_2 | F3: value_1 | G3: value_2 | H3: log2(fold_change) | L3: GRMZM5G838098 | M3: -1.35915
A4: GRMZM2G392863 | B4: GO:0006952 | C4: flower-specific gamma-thionin precursor | D4: B73 0 h | E4: B73 24 h | F4: 2.24098 | G4: 4.91922 | H4: 1.1343 | I4: 1 | L4: GRMZM2G024099 | M4: 1.42853
A5: GRMZM5G838098 | B5: NA | C5: protein tify 10a-like | D5: B73 0 h | E5: B73 24 h | F5: 6.83051 | G5: 2.66261 | H5: -1.35915 | I5: 1 | L5: AC177946.2_FG004 | M5: 1.3089
A6: GRMZM2G024099 | B6: GO:0006508GO:0004190 | C6: aspartyl protease | D6: B73 0 h | E6: B73 24 h | F6: 0.377037 | G6: 1.01488 | H6: 1.42853 | I6: 1 | L6: GRMZM2G013430 | M6: -1.06253
A7: AC177946.2_FG004 | B7: GO:0000015GO:0016020GO:0051260GO:0006096GO:0050825GO:0042309GO:0050826GO:0004634 | C7: NA | D7: B73 0 h | E7: B73 24 h | F7: 21.3595 | G7: 52.9187 | H7: 1.3089 | I7: 1 | L7: GRMZM2G331638 | M7: -1.43371
A8: GRMZM2G013430 | B8: GO:0005737GO:0006535GO:0050825GO:0042309GO:0050826GO:0009001 | C8: serine acetyltransferase mitochondrial | D8: B73 0 h | E8: B73 24 h | F8: 2.26068 | G8: 1.08239 | H8: -1.06253 | I8: 1 | L8: GRMZM2G116823 | M8: -1.62348
A9: GRMZM2G331638 | B9: NA | C9: dopamine beta-monooxygenase | D9: B73 0 h | E9: B73 24 h | F9: 1.20792 | G9: 0.447146 | H9: -1.43371 | I9: 1 | L9: GRMZM2G149647 | M9: -2.3888
A10: GRMZM2G116823 | B10: GO:0004601GO:0006979GO:0020037GO:0009055 | C10: peroxidase 53 expressed | D10: B73 0 h | E10: B73 24 h | F10: 1.29038 | G10: 0.418793 | H10: -1.62348 | I10: 1 | L10: AC208201.3_FG003 | M10: -1.98895
A11: GRMZM2G149647 | B11: NA | C11: heat-shock protein | D11: B73 0 h | E11: B73 24 h | F11: 1.36271 | G11: 0.260198 | H11: -2.3888 | I11: 1 | L11: GRMZM2G112524 | M11: 1.20116
A12: AC208201.3_FG003 | B12: NA | C12: NA | D12: B73 0 h | E12: B73 24 h | F12: 3.99423 | G12: 1.00623 | H12: -1.98895 | I12: 1 | L12: GRMZM2G318652 | M12: -1.23345
A13: GRMZM2G112524 | B13: GO:0006952GO:0009607 | C13: pathogenesis-related protein 1 | D13: B73 0 h | E13: B73 24 h | F13: 11.0341 | G13: 25.37 | H13: 1.20116 | I13: 1 | L13: GRMZM2G038153 | M13: 1.08104
A14: GRMZM2G318652 | B14: GO:0050825GO:0042309GO:0050826 | C14: sigma factor binding protein | D14: B73 0 h | E14: B73 24 h | F14: 8.20993 | G14: 3.49167 | H14: -1.23345 | I14: 1 | L14: GRMZM2G046297 | M14: -1.39912
A15: GRMZM2G038153 | B15: GO:0016829GO:0000287GO:0008152 | C15: terpene synthase 7 | D15: B73 0 h | E15: B73 24 h | F15: 1.19275 | G15: 2.52334 | H15: 1.08104 | I15: 1 | L15: GRMZM2G311036 | M15: -1.03246
... A23: GRMZM2G477139 | B23: NA | C23: thaumatin-like protein 1 precursor | D23: B73 0 h | E23: B73 24 h | F23: 0.808515 | G23: 0.0987107 | H23: -3.034 | I23: 1 | L23: GRMZM2G059064 | M23: -1.34657
A24: AC211467.4_FG002 | B24: NA | C24: NA | D24: B73 0 h | E24: B73 24 h | F24: 0 | G24: 1.2871 | H24: BD | I24: BD | L24: GRMZM2G164062 | M24: 1.28924
A25: GRMZM2G162158 | B25: GO:0005506GO:0016491 | C25: leucoanthocyanidin dioxygenase | D25: B73 0 h | E25: B73 24 h | F25: 3.68782 | G25: 1.2954 | H25: -1.50937 | I25: 1 | L25: GRMZM2G134205 | M25: -1.59159
A26: GRMZM2G059064 | B26: NA | C26: vq motif family protein | D26: B73 0 h | E26: B73 24 h | F26: 2.33988 | G26: 0.920102 | H26: -1.34657 | I26: 1 | L26: GRMZM2G359559 | M26: 3.79356
A27: GRMZM2G164062 | B27: GO:0006284GO:0008725 | C27: dna-3-methyladenine glycosylase i | D27: B73 0 h | E27: B73 24 h | F27: 0.69744 | G27: 1.70454 | H27: 1.28924 | I27: 1 | L27: GRMZM2G083538 | M27: 1.05595
A28: GRMZM2G134205 | B28: GO:0004674GO:0006468GO:0004713GO:0005524GO:0005509 | C28: wall-associated kinase 4 | D28: B73 0 h | E28: B73 24 h | F28: 1.37577 | G28: 0.456488 | H28: -1.59159 | I28: 1 | L28: GRMZM2G113165 | M28: 1.0729
A29: GRMZM2G359559 | B29: GO:0008152 | C29: alanine glyoxylate aminotransferase | D29: B73 0 h | E29: B73 24 h | F29: 0.117338 | G29: 1.6271 | H29: 3.79356 | I29: 1 | L29: GRMZM2G448151 | M29: 1.87746
A30: GRMZM2G083538 | B30: GO:0016597GO:0008152 | C30: amino acid binding | D30: B73 0 h | E30: B73 24 h | F30: 0.383311 | G30: 0.796938 | H30: 1.05595 | I30: 1 | L30: GRMZM2G448389 | M30: 1.84064
A31: GRMZM2G113165 | B31: NA | C31: carbonic anhydrase precursor | D31: B73 0 h | E31: B73 24 h | F31: 1.27573 | G31: 2.6837 | H31: 1.0729 | I31: 1 | L31: GRMZM2G048522 | M31: -2.27628
A32: GRMZM2G448151 | B32: GO:0003735GO:0015935GO:0006412GO:0003723 | C32: ribosomal protein s3 | D32: B73 0 h | E32: B73 24 h | F32: 4.09265 | G32: 15.0375 | H32: 1.87746 | I32: 1 | L32: GRMZM2G059397 | M32: -1.18182
A33: GRMZM2G448389 | B33: GO:0045261GO:0015986GO:0046961GO:0046933 | C33: atp synthase cf1 beta subunit | D33: B73 0 h | E33: B73 24 h | F33: 0.708192 | G33: 2.53652 | H33: 1.84064 | I33: 1 | L33: GRMZM2G450498 | M33: -1.66661
A34: GRMZM2G048522 | B34: NA | C34: cinnamyl alcohol dehydrogenase | D34: B73 0 h | E34: B73 24 h | F34: 0.925912 | G34: 0.191135 | H34: -2.27628 | I34: 1 | L34: GRMZM2G046700 | M34: -2.09487
A35: GRMZM2G059397 | B35: GO:0016021 | C35: senescence-associated protein | D35: B73 0 h | E35: B73 24 h | F35: 2.72801 | G35: 1.20249 | H35: -1.18182 | I35: 1 | L35: GRMZM5G827939 | M35: 2.02004
A36: GRMZM2G450498 | B36: GO:0006520GO:0030170 | C36: o-succinylhomoserine sulfhydrylase | D36: B73 0 h | E36: B73 24 h | F36: 81.4459 | G36: 25.6549 | H36: -1.66661 | I36: 1 | L36: GRMZM5G859316 | M36: -1.71625
... A69: GRMZM2G313104 | B69: GO:0050825GO:0042309GO:0050826 | C69: hypothetical protein SORBIDRAFT_01g032640 | D69: B73 0 h | E69: B73 24 h | F69: 3.14931 | G69: 1.2176 | H69: -1.37099 | I69: 1 | L69: GRMZM2G176595 | M69: 1.14279
A70: GRMZM2G425430 | B70: GO:0003700GO:0043565GO:0005634GO:0045449 | C70: wrky dna binding domain containing expressed | D70: B73 0 h | E70: B73 24 h | F70: 0 | G70: 0.862332 | H70: BD | I70: BD | L70: GRMZM2G159587 | M70: -1.14693
A71: GRMZM2G028821 | B71: GO:0005737GO:0004364GO:0008152 | C71: glutathione s-transferase | D71: B73 0 h | E71: B73 24 h | F71: 21.9374 | G71: 61.7892 | H71: 1.49396 | I71: 1 | L71: GRMZM2G004572 | M71: -1.03027
A72: GRMZM2G154565 | B72: NA | C72: hypothetical protein SORBIDRAFT_01g029090 | D72: B73 0 h | E72: B73 24 h | F72: 0.912249 | G72: 0.340232 | H72: -1.42291 | I72: 1 | L72: AC190763.3_FG002 | M72: 1.53992
A73: GRMZM2G176595 | B73: GO:0005576GO:0019953 | C73: beta-expansin 1a precursor | D73: B73 0 h | E73: B73 24 h | F73: 1.67894 | G73: 3.70723 | H73: 1.14279 | I73: 1 | L73: GRMZM2G130149 | M73: 1.11458
A74: GRMZM2G159587 | B74: GO:0005737GO:0051287GO:0006520GO:0016616GO:0005525 | C74: glyoxylate reductase | D74: B73 0 h | E74: B73 24 h | F74: 8.85601 | G74: 3.99925 | H74: -1.14693 | I74: 1 | L74: GRMZM2G136372 | M74: -4.38372
A75: GRMZM2G004572 | B75: GO:0006468GO:0004674GO:0004713GO:0005515GO:0005524GO:0031177 | C75: strubbelig-receptor family 6 | D75: B73 0 h | E75: B73 24 h | F75: 1.93596 | G75: 0.947882 | H75: -1.03027 | I75: 1 | L75: GRMZM2G402631 | M75: -1.53391
A76: AC190763.3_FG002 | B76: GO:0003887GO:0006260GO:0003677 | C76: NA | D76: B73 0 h | E76: B73 24 h | F76: 1.9573 | G76: 5.69139 | H76: 1.53992 | I76: 1 | L76: GRMZM5G893912 | M76: -2.22048
A77: GRMZM2G130149 | B77: GO:0003677 | C77: myb transcription factor | D77: B73 0 h | E77: B73 24 h | F77: 4.22049 | G77: 9.13871 | H77: 1.11458 | I77: 1 | L77: GRMZM2G023847 | M77: -1.12984
A78: GRMZM2G136372 | B78: NA | C78: pathogenesis-related protein 5 | D78: B73 0 h | E78: B73 24 h | F78: 17.7075 | G78: 0.848256 | H78: -4.38372 | I78: 1 | L78: GRMZM2G137861 | M78: -1.67215
A79: GRMZM2G402631 | B79: NA | C79: thaumatin-like protein | D79: B73 0 h | E79: B73 24 h | F79: 720.698 | G79: 248.887 | H79: -1.53391 | I79: 1 | L79: GRMZM2G362303 | M79: -1.13041
...

Sheet Mo17 6 h
A1: Table S3.Differentially expressed genes in response to R. padi feeding in B73 and Mo17 | L1: log2(fold_change)
A2: Mo17 0 h:No aphid treatment on Mo17 ,Mo17 6 h: Aphid treatment Mo17 for 6 h; NA：no annotation.BD: numerator or denominator is below of detection | K2: GRMZM2G055698 | L2: -1.65835
A3: gene | B3: GO term | C3: Description | D3: sample_1 | E3: sample_2 | F3: value_1 | G3: value_2 | H3: log2(fold_change) | K3: GRMZM2G030567 | L3: -1.05998
A4: GRMZM2G055698 | B4: GO:0016021 | C4: membrane protein | D4: Mo17 0 h | E4: Mo17 6 h | F4: 2.33823 | G4: 0.740756 | H4: -1.65835 | I4: 1 | K4: GRMZM2G099454 | L4: 1.08074
A5: GRMZM2G030567 | B5: NA | C5: hypothetical protein SORBIDRAFT_01g049390 | D5: Mo17 0 h | E5: Mo17 6 h | F5: 3.82485 | G5: 1.83454 | H5: -1.05998 | I5: 1 | K5: GRMZM2G018579 | L5: -1.38196
A6: GRMZM2G099454 | B6: GO:0004568GO:0006032GO:0016998 | C6: basic endochitinase c precursor | D6: Mo17 0 h | E6: Mo17 6 h | F6: 1.62533 | G6: 3.43778 | H6: 1.08074 | I6: 1 | K6: GRMZM2G417835 | L6: 2.77368
A7: GRMZM2G018579 | B7: NA | C7: protein | D7: Mo17 0 h | E7: Mo17 6 h | F7: 15.9681 | G7: 6.12693 | H7: -1.38196 | I7: 1 | K7: GRMZM5G838098 | L7: 1.49033
A8: GRMZM2G417835 | B8: GO:0016021GO:0007186GO:0004937 | C8: vq motif family protein | D8: Mo17 0 h | E8: Mo17 6 h | F8: 0.13027 | G8: 0.890852 | H8: 2.77368 | I8: 1 | K8: GRMZM5G815358 | L8: -1.27897
A9: GRMZM5G838098 | B9: NA | C9: protein tify 10a-like | D9: Mo17 0 h | E9: Mo17 6 h | F9: 0.965649 | G9: 2.71302 | H9: 1.49033 | I9: 1 | K9: GRMZM2G055101 | L9: -1.06425
A10: GRMZM5G815358 | B10: NA | C10: uncharacterized protein LOC100274071 | D10: Mo17 0 h | E10: Mo17 6 h | F10: 38.8951 | G10: 16.0282 | H10: -1.27897 | I10: 1 | K10: GRMZM2G013430 | L10: 1.06661
A11: GRMZM2G055101 | B11: GO:0005975GO:0004553 | C11: endo- -beta-xylanase c | D11: Mo17 0 h | E11: Mo17 6 h | F11: 1.35022 | G11: 0.645704 | H11: -1.06425 | I11: 1 | K11: GRMZM2G155242 | L11: 1.2726
A12: GRMZM2G013430 | B12: GO:0005737GO:0006535GO:0050825GO:0042309GO:0050826GO:0009001 | C12: serine acetyltransferase mitochondrial | D12: Mo17 0 h | E12: Mo17 6 h | F12: 0.988507 | G12: 2.07043 | H12: 1.06661 | I12: 1 | K12: GRMZM2G012758 | L12: 1.06455
A13: GRMZM2G155242 | B13: GO:0004512GO:0006021GO:0005488GO:0008654 | C13: inositol-3-phosphate synthase | D13: Mo17 0 h | E13: Mo17 6 h | F13: 5.01818 | G13: 12.1237 | H13: 1.2726 | I13: 1 | K13: GRMZM2G149647 | L13: 1.60209
A14: GRMZM2G012758 | B14: GO:0005975GO:0004553 | C14: glucan endo- -beta-glucosidase 7-like | D14: Mo17 0 h | E14: Mo17 6 h | F14: 11.6166 | G14: 24.2963 | H14: 1.06455 | I14: 1 | K14: RPS20 | L14: 1.03609
A15: GRMZM2G149647 | B15: NA | C15: heat-shock protein | D15: Mo17 0 h | E15: Mo17 6 h | F15: 1.11351 | G15: 3.38041 | H15: 1.60209 | I15: 1 | K15: GRMZM2G341309 | L15: 1.87857
... A75: GRMZM2G178852 | B75: GO:0050825GO:0042309GO:0050826 | C75: uncharacterized protein LOC100277616 | D75: Mo17 0 h | E75: Mo17 6 h | F75: 0.653669 | G75: 1.36274 | H75: 1.05988 | I75: 1 | K75: GRMZM2G139852 | L75: -1.66207
A76: GRMZM2G380789 | B76: GO:0016021 | C76: heptahelical protein 4 | D76: Mo17 0 h | E76: Mo17 6 h | F76: 0 | G76: 0.772956 | H76: BD | I76: BD | K76: GRMZM5G818431 | L76: 1.03301
A77: GRMZM2G153920 | B77: GO:0022891GO:0016021GO:0055085 | C77: sorbitol transporter | D77: Mo17 0 h | E77: Mo17 6 h | F77: 1.67006 | G77: 4.75752 | H77: 1.51031 | I77: 1 | K77: GRMZM2G077942 | L77: 1.13974
A78: GRMZM2G139852 | B78: NA | C78: integral membrane family protein | D78: Mo17 0 h | E78: Mo17 6 h | F78: 1.17637 | G78: 0.371714 | H78: -1.66207 | I78: 1 | K78: AC177947.2_FG003 | L78: -1.38687
A79: GRMZM5G818431 | B79: NA | C79: atp binding | D79: Mo17 0 h | E79: Mo17 6 h | F79: 4.09613 | G79: 8.38187 | H79: 1.03301 | I79: 1 | K79: GRMZM2G149636 | L79: 1.41172
A80: GRMZM2G077942 | B80: GO:0003779GO:0005622 | C80: actin-depolymerizing factor 5 | D80: Mo17 0 h | E80: Mo17 6 h | F80: 25.6743 | G80: 56.571 | H80: 1.13974 | I80: 1 | K80: GRMZM2G042253 | L80: -1.25474
A81: AC177947.2_FG003 | B81: NA | C81: NA | D81: Mo17 0 h | E81: Mo17 6 h | F81: 1.95966 | G81: 0.749362 | H81: -1.38687 | I81: 1 | K81: GRMZM2G321033 | L81: 1.52037
A82: GRMZM2G149636 | B82: GO:0006633GO:0016020GO:0008415 | C82: 3-ketoacyl- synthase 1 | D82: Mo17 0 h | E82: Mo17 6 h | F82: 7.37233 | G82: 19.6144 | H82: 1.41172 | I82: 1 | K82: GRMZM2G102483 | L82: 1.10906
A83: GRMZM2G042253 | B83: GO:0005737GO:0006457GO:0005524GO:0005515 | C83: ru large subunit-binding protein subunit chloroplastic-like | D83: Mo17 0 h | E83: Mo17 6 h | F83: 57.593 | G83: 24.1354 | H83: -1.25474 | I83: 1 | K83: GRMZM2G136513 | L83: 1.13635
A84: GRMZM2G321033 | B84: GO:0004497GO:0020037GO:0009055 | C84: cytochrome p450 family expressed | D84: Mo17 0 h | E84: Mo17 6 h | F84: 0.440711 | G84: 1.26425 | H84: 1.52037 | I84: 1 | K84: GRMZM5G883632 | L84: -1.06668
A85: GRMZM2G102483 | B85: NA | C85: 39 kda ef-hand containing expressed | D85: Mo17 0 h | E85: Mo17 6 h | F85: 2.3792 | G85: 5.13206 | H85: 1.10906 | I85: 1 | K85: GRMZM2G043878 | L85: 2.47032
A86: GRMZM2G136513 | B86: GO:0006915GO:0017111GO:0005515GO:0005524 | C86: nb-arc domain containing expressed | D86: Mo17 0 h | E86: Mo17 6 h | F86: 0.52422 | G86: 1.15236 | H86: 1.13635 | I86: 1 | K86: GRMZM2G338037 | L86: 1.37713
A87: GRMZM5G883632 | B87: NA | C87: protein faf- chloroplastic-like | D87: Mo17 0 h | E87: Mo17 6 h | F87: 2.24596 | G87: 1.07226 | H87: -1.06668 | I87: 1 | K87: GRMZM2G010909 | L87: 1.243
A88: GRMZM2G043878 | B88: NA | C88: 33-kda secretory protein | D88: Mo17 0 h | E88: Mo17 6 h | F88: 0.676128 | G88: 3.74689 | H88: 2.47032 | I88: 1 | K88: GRMZM2G089720 | L88: 2.07047
... A130: GRMZM2G043191 | B130: GO:0004437 | C130: type i inositol- -trisphosphate 5-phosphatase 11-like | D130: Mo17 0 h | E130: Mo17 6 h | F130: 1.34727 | G130: 2.87384 | H130: 1.09294 | I130: 1 | K130: GRMZM2G128564 | L130: 1.23599
A131: GRMZM2G004106 | B131: GO:0005507GO:0009055 | C131: chemocyanin precursor | D131: Mo17 0 h | E131: Mo17 6 h | F131: 0 | G131: 2.86138 | H131: BD | I131: BD | K131: GRMZM2G011367 | L131: -1.22842
A132: GRMZM2G004160 | B132: GO:0005507GO:0009055 | C132: chemocyanin precursor | D132: Mo17 0 h | E132: Mo17 6 h | F132: 0.776626 | G132: 3.2541 | H132: 2.06697 | I132: 1 | K132: GRMZM2G039278 | L132: 1.03587
A133: GRMZM2G054361 | B133: GO:0016847GO:0009058GO:0030170GO:0016769 | C133: NA | D133: Mo17 0 h | E133: Mo17 6 h | F133: 2.77873 | G133: 6.61661 | H133: 1.25166 | I133: 1 | K133: GRMZM2G427697 | L133: -1.38817
A134: GRMZM2G128564 | B134: GO:0016747 | C134: hydroxycinnamoyl-coenzyme a shikimate quinate hydroxycinnamoyltransferase-like | D134: Mo17 0 h | E134: Mo17 6 h | F134: 3.81942 | G134: 8.99639 | H134: 1.23599 | I134: 1 | K134: GRMZM2G093776 | L134: 1.09722
A135: GRMZM2G011367 | B135: NA | C135: hypothetical protein | D135: Mo17 0 h | E135: Mo17 6 h | F135: 87.256 | G135: 37.2395 | H135: -1.22842 | I135: 1 | K135: GRMZM5G883969 | L135: 1.16615
A136: GRMZM2G039278 | B136: GO:0004497GO:0020037GO:0009055 | C136: cytochrome p450 | D136: Mo17 0 h | E136: Mo17 6 h | F136: 5.80953 | G136: 11.9116 | H136: 1.03587 | I136: 1 | K136: GRMZM2G044317 | L136: -1.23868
A137: GRMZM2G427697 | B137: NA | C137: unknown | D137: Mo17 0 h | E137: Mo17 6 h | F137: 14.713 | G137: 5.6211 | H137: -1.38817 | I137: 1 | K137: GRMZM5G839644 | L137: 1.57574
A138: GRMZM2G093776 | B138: GO:0006508GO:0004197 | C138: protein phosphatase 2c 23 | D138: Mo17 0 h | E138: Mo17 6 h | F138: 1.00902 | G138: 2.15872 | H138: 1.09722 | I138: 1 | K138: GRMZM2G565911 | L138: 1.84943
A139: GRMZM5G883969 | B139: NA | C139: unknown | D139: Mo17 0 h | E139: Mo17 6 h | F139: 0.623367 | G139: 1.39891 | H139: 1.16615 | I139: 1 | K139: GRMZM5G816432 | L139: 1.06999
A140: GRMZM2G044317 | B140: GO:0005658GO:0006269GO:0003896 | C140: dna primase large subunit | D140: Mo17 0 h | E140: Mo17 6 h | F140: 1.76997 | G140: 0.750044 | H140: -1.23868 | I140: 1 | K140: GRMZM2G146981 | L140: -1.03139
...

Sheet Mo17 24 h
A1: Table S3. Differentially expressed genes in response to R. padi feeding in B73 and Mo17 | L1: log2(fold_change)
A2: Mo17 0 h:No aphid treatment on Mo17 ,Mo17 24 h: Aphid treatment Mo17 for 24 h; NA：no annotation.BD: numerator or denominator is below of detection | K2: GRMZM2G392863 | L2: 1.09577
A3: gene | B3: GO term | C3: Description | D3: sample_1 | E3: sample_2 | F3: value_1 | G3: value_2 | H3: log2(fold_change) | K3: GRMZM2G099454 | L3: 1.56031
A4: GRMZM2G392863 | B4: GO:0006952 | C4: flower-specific gamma-thionin precursor | D4: MT0 | E4: MT24 | F4: 5.23575 | G4: 11.1902 | H4: 1.09577 | I4: 1 | K4: GRMZM2G018579 | L4: 1.02408
A5: GRMZM2G099454 | B5: GO:0004568GO:0006032GO:0016998 | C5: basic endochitinase c precursor | D5: MT0 | E5: MT24 | F5: 1.62533 | G5: 4.79337 | H5: 1.56031 | I5: 1 | K5: GRMZM2G031790 | L5: -1.03628
A6: GRMZM2G018579 | B6: NA | C6: protein | D6: MT0 | E6: MT24 | F6: 15.9681 | G6: 32.4738 | H6: 1.02408 | I6: 1 | K6: AC177946.2_FG004 | L6: -1.23101
A7: GRMZM2G031790 | B7: GO:0006633GO:0016020GO:0008415 | C7: 3-ketoacyl- synthase 11-like | D7: MT0 | E7: MT24 | F7: 12.4711 | G7: 6.08072 | H7: -1.03628 | I7: 1 | K7: GRMZM2G703561 | L7: -1.29249
A8: AC177946.2_FG004 | B8: GO:0000015GO:0016020GO:0051260GO:0006096GO:0050825GO:0042309GO:0050826GO:0004634 | C8: NA | D8: MT0 | E8: MT24 | F8: 11.676 | G8: 4.9742 | H8: -1.23101 | I8: 1 | K8: AC208201.3_FG003 | L8: 1.52455
A9: GRMZM2G703561 | B9: NA | C9: NA | D9: MT0 | E9: MT24 | F9: 1.4095 | G9: 0.575422 | H9: -1.29249 | I9: 1 | K9: GRMZM2G340286 | L9: -1.41743
A10: AC208201.3_FG003 | B10: NA | C10: NA | D10: MT0 | E10: MT24 | F10: 1.01672 | G10: 2.92508 | H10: 1.52455 | I10: 1 | K10: GRMZM2G093962 | L10: -1.13013
A11: GRMZM2G340286 | B11: NA | C11: uncharacterized protein LOC100275916 | D11: MT0 | E11: MT24 | F11: 0.757095 | G11: 0.28344 | H11: -1.41743 | I11: 1 | K11: GRMZM2G099467 | L11: 2.12729
A12: GRMZM2G093962 | B12: GO:0016021 | C12: membrane protein | D12: MT0 | E12: MT24 | F12: 1.05882 | G12: 0.483746 | H12: -1.13013 | I12: 1 | K12: GRMZM2G037265 | L12: -1.03303
A13: GRMZM2G099467 | B13: GO:0005506GO:0016491 | C13: 2og-fe oxygenase family expressed | D13: MT0 | E13: MT24 | F13: 1.77208 | G13: 7.74218 | H13: 2.12729 | I13: 1 | K13: GRMZM2G059129 | L13: 1.20157
A14: AC199487.4_FG002 | B14: GO:0009611GO:0004867 | C14: NA | D14: MT0 | E14: MT24 | F14: 1.8738 | G14: 0 | H14: BD | I14: BD | K14: GRMZM2G141607 | L14: -1.04695
A15: GRMZM2G037265 | B15: NA | C15: alkaline alpha-galactosidase seed imbibition protein | D15: MT0 | E15: MT24 | F15: 66.7809 | G15: 32.6347 | H15: -1.03303 | I15: 1 | K15: GRMZM2G324999 | L15: 1.58046
A16: GRMZM2G059129 | B16: GO:0006071GO:0006629GO:0008889 | C16: probable glycerophosphoryl diester phosphodiesterase 2-like | D16: MT0 | E16: MT24 | F16: 2.10103 | G16: 4.83217 | H16: 1.20157 | I16: 1 | K16: GRMZM2G130904 | L16: 1.73831
A17: GRMZM2G141607 | B17: GO:0009239GO:0005488GO:0008667 | C17: 3-ketoacyl- reductase | D17: MT0 | E17: MT24 | F17: 1.74996 | G17: 0.846965 | H17: -1.04695 | I17: 1 | K17: GRMZM2G162505 | L17: 1.34372
A18: GRMZM2G324999 | B18: GO:0003700GO:0043565GO:0005634GO:0045449 | C18: wrky69 - superfamily of tfs having wrky and zinc finger domains | D18: MT0 | E18: MT24 | F18: 0.342934 | G18: 1.02559 | H18: 1.58046 | I18: 1 | K18: GRMZM5G805732 | L18: 1.09902
A19: GRMZM2G130904 | B19: GO:0004601GO:0006979GO:0020037GO:0009055 | C19: peroxidase n-like | D19: MT0 | E19: MT24 | F19: 0.376376 | G19: 1.25576 | H19: 1.73831 | I19: 1 | K19: GRMZM2G021055 | L19: 1.19608
A20: GRMZM2G162505 | B20: GO:0004568GO:0006032 | C20: chitinase 2-like | D20: MT0 | E20: MT24 | F20: 0.492076 | G20: 1.24891 | H20: 1.34372 | I20: 1 | K20: GRMZM2G059964 | L20: 1.08621
A21: GRMZM5G805732 | B21: NA | C21: cationic amino acid transporter | D21: MT0 | E21: MT24 | F21: 0.53335 | G21: 1.14248 | H21: 1.09902 | I21: 1 | K21: GRMZM2G090043 | L21: 1.23823
A22: GRMZM2G021055 | B22: GO:0015297GO:0016020GO:0006855GO:0015238 | C22: protein transparent testa 12-like | D22: MT0 | E22: MT24 | F22: 0.421456 | G22: 0.965625 | H22: 1.19608 | I22: 1 | K22: GRMZM2G301089 | L22: 1.14135
A23: GRMZM2G059964 | B23: NA | C23: cortical cell-delineating protein precursor | D23: MT0 | E23: MT24 | F23: 4.13676 | G23: 8.78299 | H23: 1.08621 | I23: 1 | K23: GRMZM2G475948 | L23: 1.11486
A24: GRMZM2G090043 | B24: NA | C24: hypothetical protein | D24: MT0 | E24: MT24 | F24: 1.08726 | G24: 2.56493 | H24: 1.23823 | I24: 1 | K24: GRMZM2G013206 | L24: 2.07066
A25: GRMZM2G301089 | B25: GO:0005634GO:0045449GO:0030528 | C25: transcription factor bhlh92 | D25: MT0 | E25: MT24 | F25: 1.57118 | G25: 3.46582 | H25: 1.14135 | I25: 1 | K25: GRMZM2G008064 | L25: 1.29519
A26: GRMZM2G475948 | B26: GO:0004674GO:0006468GO:0005529GO:0004713GO:0005524 | C26: l-type lectin-domain containing receptor kinase -like | D26: MT0 | E26: MT24 | F26: 2.20649 | G26: 4.77868 | H26: 1.11486 | I26: 1 | K26: GRMZM2G153920 | L26: 1.00429
... A55: GRMZM2G104489 | B55: GO:0008270GO:0005622 | C55: uncharacterized protein LOC100272609 | D55: MT0 | E55: MT24 | F55: 18.112 | G55: 7.12534 | H55: -1.34592 | I55: 1 | K55: GRMZM2G401883 | L55: 1.21257
A56: GRMZM2G127336 | B56: GO:0016829GO:0000287GO:0008152 | C56: #NAME? | D56: MT0 | E56: MT24 | F56: 0.500957 | G56: 1.38585 | H56: 1.46801 | I56: 1 | K56: GRMZM2G436448 | L56: 1.46517
A57: GRMZM2G176998 | B57: NA | C57: wd40-like beta propeller repeat family expressed | D57: MT0 | E57: MT24 | F57: 1.59061 | G57: 3.55818 | H57: 1.16156 | I57: 1 | K57: GRMZM2G119823 | L57: 1.07597
A58: GRMZM2G401883 | B58: NA | C58: uncharacterized protein LOC100276969 | D58: MT0 | E58: MT24 | F58: 1.59565 | G58: 3.69792 | H58: 1.21257 | I58: 1 | K58: GRMZM5G894619 | L58: 1.0529
A59: GRMZM2G436448 | B59: GO:0004674GO:0006468GO:0004713GO:0005524 | C59: rust resistance kinase lr10 | D59: MT0 | E59: MT24 | F59: 2.64149 | G59: 7.29302 | H59: 1.46517 | I59: 1 | K59: GRMZM2G429000 | L59: -1.38844
A60: GRMZM2G119823 | B60: GO:0005634GO:0045449GO:0030528 | C60: transcription factor bhlh35 | D60: MT0 | E60: MT24 | F60: 1.99267 | G60: 4.20081 | H60: 1.07597 | I60: 1 | K60: GRMZM2G085236 | L60: 1.06213
A61: GRMZM5G894619 | B61: NA | C61: 1-aminocyclopropane-1-carboxylate synthase | D61: MT0 | E61: MT24 | F61: 0.654279 | G61: 1.35743 | H61: 1.0529 | I61: 1 | K61: GRMZM2G084576 | L61: -1.11801
A62: GRMZM2G429000 | B62: NA | C62: cortical cell-delineating protein precursor | D62: MT0 | E62: MT24 | F62: 4.97175 | G62: 1.8991 | H62: -1.38844 | I62: 1 | K62: GRMZM2G018716 | L62: 1.09427
A63: GRMZM2G085236 | B63: GO:0042626GO:0016021GO:0006810GO:0019001GO:0004871GO:0007186GO:0005524 | C63: abc transporter b family member 19-like | D63: MT0 | E63: MT24 | F63: 0.423502 | G63: 0.884278 | H63: 1.06213 | I63: 1 | K63: GRMZM2G072820 | L63: -1.16036
A64: GRMZM2G084576 | B64: GO:0005634GO:0045449GO:0030528 | C64: ili1 binding bhlh 1 protein | D64: MT0 | E64: MT24 | F64: 1.42134 | G64: 0.654851 | H64: -1.11801 | I64: 1 | K64: GRMZM2G071771 | L64: 1.08852
A65: GRMZM2G018716 | B65: GO:0006508GO:0005975GO:0004252GO:0004553 | C65: glycosy1 hydrolase | D65: MT0 | E65: MT24 | F65: 0.724397 | G65: 1.54662 | H65: 1.09427 | I65: 1 | K65: GRMZM2G050216 | L65: 1.22411
A66: GRMZM2G072820 | B66: GO:0005634GO:0045449GO:0030528 | C66: transcription factor | D66: MT0 | E66: MT24 | F66: 18.9876 | G66: 8.4951 | H66: -1.16036 | I66: 1 | K66: GRMZM2G118345 | L66: 1.15787
A67: GRMZM2G071771 | B67: GO:0008289GO:0006869 | C67: pvr3-like protein | D67: MT0 | E67: MT24 | F67: 10.4535 | G67: 22.2299 | H67: 1.08852 | I67: 1 | K67: LIP | L67: -1.46288
A68: GRMZM2G050216 | B68: GO:0008270GO:0005515 | C68: zinc c3hc4 type family protein | D68: MT0 | E68: MT24 | F68: 2.10982 | G68: 4.9288 | H68: 1.22411 | I68: 1 | K68: GRMZM2G119975 | L68: 1.49532
...

Sheet up-regulated in B73 6 h
A1: Table S3. Differentially expressed genes in response to R. padi feeding in B73 and Mo17
A2: Genes up- and down-regulated by R. padi treatment in B73 and Mo17.
A3: B73 0 h:No aphid treatment on B73,B73 6 h: Aphid treatment B73 for 6 h; NA：no annotation.BD: numerator or denominator is below of detection
A4: Gene ID | B4: GO term | C4: Description | D4: sample_1 | E4: sample_2 | F4: value_1 | G4: value_2 | H4: log2(fold_change)
A5: GRMZM2G474039 | B5: =VLOOKUP($A5,[1]Sheet1!$A:$B,2,FALSE) -> #N/A | C5: hypothetical protein SORBIDRAFT_06g030720 | D5: B73 0 h | E5: B73 6 h | F5: 0.451313 | G5: 15.3552 | H5: 5.08845 | I5: NA
A6: GRMZM5G891371 | B6: =VLOOKUP($A6,[1]Sheet1!$A:$B,2,FALSE) -> #N/A | C6: subtilase family protein | D6: B73 0 h | E6: B73 6 h | F6: 0.191896 | G6: 5.83183 | H6: 4.92556 | I6: NA
A7: GRMZM2G028640 | B7: =VLOOKUP($A7,[1]Sheet1!$A:$B,2,FALSE) -> #N/A | C7: enzyme of the cupin superfamily | D7: B73 0 h | E7: B73 6 h | F7: 0.626461 | G7: 12.7577 | H7: 4.348 | I7: NA
A8: AC208221.3_FG002 | B8: =VLOOKUP($A8,[1]Sheet1!$A:$B,2,FALSE) -> GO:0005576GO:0004867 | C8: NA | D8: B73 0 h | E8: B73 6 h | F8: 1.01293 | G8: 20.1457 | H8: 4.31387 | I8: GO:0005576GO:0004867
A9: GRMZM2G018988 | B9: =VLOOKUP($A9,[1]Sheet1!$A:$B,2,FALSE) -> #N/A | C9: protein | D9: B73 0 h | E9: B73 6 h | F9: 0.154308 | G9: 2.73413 | H9: 4.14719 | I9: NA
A10: GRMZM2G308619 | B10: =VLOOKUP($A10,[1]Sheet1!$A:$B,2,FALSE) -> GO:0004674GO:0006468GO:0004713GO:0005524 | C10: protein kinase g11a-like | D10: B73 0 h | E10: B73 6 h | F10: 0.0615478 | G10: 1.05604 | H10: 4.10081 | I10: GO:0004674GO:0006468GO:0004713GO:0005524
A11: GRMZM2G045031 | B11: =VLOOKUP($A11,[1]Sheet1!$A:$B,2,FALSE) -> #N/A | C11: uncharacterized protein LOC100278663 | D11: B73 0 h | E11: B73 6 h | F11: 0.497457 | G11: 8.33092 | H11: 4.06583 | I11: NA
A12: AC233910.1_FG003 | B12: =VLOOKUP($A12,[1]Sheet1!$A:$B,2,FALSE) -> GO:0003735GO:0006412GO:0006464GO:0005840 | C12: NA | D12: B73 0 h | E12: B73 6 h | F12: 0.77188 | G12: 12.0535 | H12: 3.96494 | I12: GO:0003735GO:0006412GO:0006464GO:0005840
A13: GRMZM2G380789 | B13: =VLOOKUP($A13,[1]Sheet1!$A:$B,2,FALSE) -> GO:0016021 | C13: heptahelical protein 4 | D13: B73 0 h | E13: B73 6 h | F13: 0.0796325 | G13: 1.14939 | H13: 3.85137 | I13: GO:0016021
A14: GRMZM2G058681 | B14: =VLOOKUP($A14,[1]Sheet1!$A:$B,2,FALSE) -> GO:0003735GO:0008270GO:0006412GO:0005840 | C14: protein | D14: B73 0 h | E14: B73 6 h | F14: 0.68254 | G14: 7.59614 | H14: 3.47628 | I14: GO:0003735GO:0008270GO:0006412GO:0005840
A15: GRMZM5G827939 | B15: =VLOOKUP($A15,[1]Sheet1!$A:$B,2,FALSE) -> #N/A | C15: -dihydroxy-3-keto-5-methylthiopentene dioxygenase 4 | D15: B73 0 h | E15: B73 6 h | F15: 1.17746 | G15: 12.6069 | H15: 3.42046 | I15: NA
A16: GRMZM2G056697 | B16: =VLOOKUP($A16,[1]Sheet1!$A:$B,2,FALSE) -> #N/A | C16: uncharacterized protein LOC100272757 | D16: B73 0 h | E16: B73 6 h | F16: 0.103158 | G16: 1.08331 | H16: 3.39252 | I16: NA
... A298: GRMZM2G113060 | B298: =VLOOKUP($A298,[1]Sheet1!$A:$B,2,FALSE) -> GO:0003700GO:0006355 | C298: dre binding factor | D298: B73 0 h | E298: B73 6 h | F298: 8.18782 | G298: 16.3776 | H298: 1.00017 | I298: GO:0003700GO:0006355
A299: GRMZM5G855014 | B299: =VLOOKUP($A299,[1]Sheet1!$A:$B,2,FALSE) -> #N/A | C299: unknown | D299: B73 0 h | E299: B73 6 h | F299: 0 | G299: 1.36839 | H299: BD | I299: NA
A300: GRMZM2G143142 | B300: =VLOOKUP($A300,[1]Sheet1!$A:$B,2,FALSE) -> #N/A | C300: NA | D300: B73 0 h | E300: B73 6 h | F300: 0 | G300: 1.47512 | H300: BD | I300: NA
A301: GRMZM2G327199 | B301: =VLOOKUP($A301,[1]Sheet1!$A:$B,2,FALSE) -> #N/A | C301: NA | D301: B73 0 h | E301: B73 6 h | F301: 0 | G301: 4.84134 | H301: BD | I301: NA
A302: GRMZM2G344279 | B302: =VLOOKUP($A302,[1]Sheet1!$A:$B,2,FALSE) -> GO:0003735GO:0015934GO:0006412GO:0030528 | C302: 60s ribosomal protein l7-1 | D302: B73 0 h | E302: B73 6 h | F302: 0 | G302: 1.06424 | H302: BD | I302: GO:0003735GO:0015934GO:0006412GO:0030528
A303: GRMZM2G164761 | B303: =VLOOKUP($A303,[1]Sheet1!$A:$B,2,FALSE) -> GO:0016020GO:0016760GO:0030244 | C303: cellulose synthase-like protein slf1 | D303: B73 0 h | E303: B73 6 h | F303: 0 | G303: 0.99544 | H303: BD | I303: GO:0016020GO:0016760GO:0030244
A304: GRMZM2G148316 | B304: =VLOOKUP($A304,[1]Sheet1!$A:$B,2,FALSE) -> #N/A | C304: cytokinin-o-glucosyltransferase 2 | D304: B73 0 h | E304: B73 6 h | F304: 0 | G304: 1.20052 | H304: BD | I304: NA
A305: GRMZM2G121264 | B305: =VLOOKUP($A305,[1]Sheet1!$A:$B,2,FALSE) -> GO:0004497GO:0020037GO:0009055 | C305: protein | D305: B73 0 h | E305: B73 6 h | F305: 0 | G305: 1.53659 | H305: BD | I305: GO:0004497GO:0020037GO:0009055
A306: GRMZM2G703156 | B306: =VLOOKUP($A306,[1]Sheet1!$A:$B,2,FALSE) -> #N/A | C306: NA | D306: B73 0 h | E306: B73 6 h | F306: 0 | G306: 3.7902 | H306: BD | I306: NA
A307: GRMZM2G434572 | B307: =VLOOKUP($A307,[1]Sheet1!$A:$B,2,FALSE) -> GO:0046872GO:0019509GO:0051213 | C307: -dihydroxy-3-keto-5-methylthiopentene dioxygenase 4 | D307: B73 0 h | E307: B73 6 h | F307: 0 | G307: 1.88209 | H307: BD | I307: GO:0046872GO:0019509GO:0051213
A308: GRMZM2G701791 | B308: =VLOOKUP($A308,[1]Sheet1!$A:$B,2,FALSE) -> #N/A | C308: NA | D308: B73 0 h | E308: B73 6 h | F308: 0 | G308: 1.58804 | H308: BD | I308: NA
A309: AC233880.1_FG009 | B309: =VLOOKUP($A309,[1]Sheet1!$A:$B,2,FALSE) -> GO:0003735GO:0004812GO:0005840GO:0005524GO:0006418 | C309: NA | D309: B73 0 h | E309: B73 6 h | F309: 0 | G309: 0.823119 | H309: BD | I309: GO:0003735GO:0004812GO:0005840GO:0005524GO:0006418
A310: GRMZM2G003014 | B310: =VLOOKUP($A310,[1]Sheet1!$A:$B,2,FALSE) -> #N/A | C310: nucleotide-diphospho-sugar transferases superfamily protein | D310: B73 0 h | E310: B73 6 h | F310: 0 | G310: 1.69197 | H310: BD | I310: NA
... A323: GRMZM2G070115 | B323: =VLOOKUP($A323,[1]Sheet1!$A:$B,2,FALSE) -> #N/A | C323: protein cdc2 kinase | D323: B73 0 h | E323: B73 6 h | F323: 0 | G323: 1.45979 | H323: BD | I323: NA

Sheet up-regulated in B73 24 h
A1: Table S3. Differentially expressed genes in response to R. padi feeding in B73 and Mo17
A2: Genes up- and down-regulated by R. padi treatment in B73 and Mo17.
A3: B73 0 h:No aphid treatment on B73,B73 24 h: Aphid treatment B73 for 24 h; NA：no annotation.BD: numerator or denominator is below of detection
A4: Gene ID | B4: GO term | C4: Description | D4: sample_1 | E4: sample_2 | F4: value_1 | G4: value_2 | H4: log2(fold_change)
A5: GRMZM2G028640 | B5: NA | C5: enzyme of the cupin superfamily | D5: B73 0 h | E5: B73 24 h | F5: 0.626461 | G5: 38.7026 | H5: 5.94906
A6: GRMZM5G891371 | B6: NA | C6: subtilase family protein | D6: B73 0 h | E6: B73 24 h | F6: 0.191896 | G6: 7.97984 | H6: 5.37797
A7: AC208221.3_FG002 | B7: GO:0005576GO:0004867 | C7: NA | D7: B73 0 h | E7: B73 24 h | F7: 1.01293 | G7: 35.8602 | H7: 5.14578
A8: GRMZM2G359559 | B8: GO:0008152 | C8: alanine glyoxylate aminotransferase | D8: B73 0 h | E8: B73 24 h | F8: 0.117338 | G8: 1.6271 | H8: 3.79356
A9: GRMZM2G143403 | B9: GO:0008270GO:0003676 | C9: protein | D9: B73 0 h | E9: B73 24 h | F9: 0.449578 | G9: 4.5031 | H9: 3.32428
A10: GRMZM2G108153 | B10: GO:0004601GO:0006979GO:0020037GO:0009055 | C10: protein | D10: B73 0 h | E10: B73 24 h | F10: 0.261235 | G10: 1.63542 | H10: 2.64624
A11: GRMZM2G428040 | B11: NA | C11: transcription activator-related protein | D11: B73 0 h | E11: B73 24 h | F11: 0.211526 | G11: 1.27582 | H11: 2.59253
A12: GRMZM2G124759 | B12: GO:0004806GO:0006629 | C12: triacylglycerol lipase | D12: B73 0 h | E12: B73 24 h | F12: 1.94963 | G12: 11.5223 | H12: 2.56316
A13: GRMZM2G140107 | B13: GO:0009058GO:0046524GO:0005985 | C13: sucrose phosphate synthase | D13: B73 0 h | E13: B73 24 h | F13: 0.164627 | G13: 0.922441 | H13: 2.48626
A14: GRMZM2G455676 | B14: GO:0009654GO:0015979 | C14: photosystem ii reaction center w protein | D14: B73 0 h | E14: B73 24 h | F14: 0.875705 | G14: 4.88799 | H14: 2.48072
A15: GRMZM2G032721 | B15: GO:0003735GO:0009536GO:0006412GO:0005840 | C15: plastid-specific 30s ribosomal protein 3 | D15: B73 0 h | E15: B73 24 h | F15: 2.65195 | G15: 14.1864 | H15: 2.41939
A16: GRMZM2G429955 | B16: GO:0016020GO:0009765 | C16: chlorophyll a-b binding protein 2 | D16: B73 0 h | E16: B73 24 h | F16: 86.6253 | G16: 428.193 | H16: 2.3054
... A176: GRMZM2G319109 | B176: GO:0003924GO:0005525GO:0004789GO:0009228GO:0005622 | C176: fzo-like protein | D176: B73 0 h | E176: B73 24 h | F176: 10.2421 | G176: 20.5258 | H176: 1.00293
A177: AC211467.4_FG002 | B177: NA | C177: NA | D177: B73 0 h | E177: B73 24 h | F177: 0 | G177: 1.2871 | H177: BD
A178: GRMZM2G425430 | B178: GO:0003700GO:0043565GO:0005634GO:0045449 | C178: wrky dna binding domain containing expressed | D178: B73 0 h | E178: B73 24 h | F178: 0 | G178: 0.862332 | H178: BD
A179: GRMZM2G478779 | B179: GO:0006139GO:0005524GO:0005515GO:0019205 | C179: actin | D179: B73 0 h | E179: B73 24 h | F179: 0 | G179: 0.996515 | H179: BD
A180: GRMZM2G019085 | B180: NA | C180: NA | D180: B73 0 h | E180: B73 24 h | F180: 0 | G180: 2.12714 | H180: BD
A181: GRMZM5G807110 | B181: NA | C181: uncharacterized protein LOC100382421 | D181: B73 0 h | E181: B73 24 h | F181: 0 | G181: 1.44764 | H181: BD
A182: GRMZM2G157869 | B182: NA | C182: hypersensitive-induced response protein | D182: B73 0 h | E182: B73 24 h | F182: 0 | G182: 1.16416 | H182: BD
A183: GRMZM2G546097 | B183: NA | C183: NA | D183: B73 0 h | E183: B73 24 h | F183: 0 | G183: 4.25102 | H183: BD
A184: GRMZM2G065652 | B184: NA | C184: uncharacterized protein LOC100272674 | D184: B73 0 h | E184: B73 24 h | F184: 0 | G184: 2.05262 | H184: BD
A185: GRMZM2G425136 | B185: GO:0016740GO:0050825GO:0042309GO:0008152GO:0050826 | C185: psbp domain-containing protein chloroplastic-like | D185: B73 0 h | E185: B73 24 h | F185: 0 | G185: 1.73815 | H185: BD
A186: AC187896.3_FG006 | B186: NA | C186: NA | D186: B73 0 h | E186: B73 24 h | F186: 0 | G186: 0.958736 | H186: BD
A187: GRMZM2G063583 | B187: NA | C187: hypothetical protein SORBIDRAFT_03g026630 | D187: B73 0 h | E187: B73 24 h | F187: 0 | G187: 5.81766 | H187: BD
A188: GRMZM5G807957 | B188: NA | C188: NA | D188: B73 0 h | E188: B73 24 h | F188: 0 | G188: 0.998317 | H188: BD
A189: GRMZM5G890783 | B189: NA | C189: uncharacterized protein LOC100279463 | D189: B73 0 h | E189: B73 24 h | F189: 0 | G189: 13.0952 | H189: BD

Sheet up-regulated in Mo17 6 h
A1: Table S3. Differentially expressed genes in response to R. padi feeding in B73 and Mo17
A2: Genes up- and down-regulated by R. padi treatment in B73 and Mo17.
A3: Mo17 0 h:No aphid treatment on Mo17, Mo17 6 h: Aphid treatment Mo17 for 6 h; NA：no annotation.BD: numerator or denominator is below of detection
A4: Gene ID | B4: GO term | C4: Description | D4: sample_1 | E4: sample_2 | F4: value_1 | G4: value_2 | H4: log2(fold_change)
A5: GRMZM2G045031 | B5: NA | C5: uncharacterized protein LOC100278663 | D5: Mo17 0 h | E5: Mo17 6 h | F5: 0.138254 | G5: 11.495 | H5: 6.37754
A6: GRMZM2G468111 | B6: NA | C6: uncharacterized protein LOC100277849 | D6: Mo17 0 h | E6: Mo17 6 h | F6: 1.70723 | G6: 62.0608 | H6: 5.18395
A7: GRMZM2G133988 | B7: GO:0008152 | C7: 3-isopropylmalate dehydratase-like | D7: Mo17 0 h | E7: Mo17 6 h | F7: 1.19113 | G7: 41.422 | H7: 5.11999
A8: GRMZM2G010044 | B8: GO:0008652GO:0016836GO:0051539 | C8: 3-isopropylmalate dehydratase | D8: Mo17 0 h | E8: Mo17 6 h | F8: 6.3386 | G8: 201.729 | H8: 4.99211
A9: GRMZM2G117706 | B9: GO:0020037GO:0005576GO:0004601GO:0006979GO:0009055 | C9: bacterial-induced peroxidase precursor | D9: Mo17 0 h | E9: Mo17 6 h | F9: 0.404387 | G9: 8.20211 | H9: 4.34219
A10: GRMZM2G162505 | B10: GO:0004568GO:0006032 | C10: chitinase 2-like | D10: Mo17 0 h | E10: Mo17 6 h | F10: 0.492076 | G10: 8.6512 | H10: 4.13595
A11: GRMZM2G465226 | B11: NA | C11: pathogenesis-related protein class i | D11: Mo17 0 h | E11: Mo17 6 h | F11: 1.14524 | G11: 16.4295 | H11: 3.84256
A12: GRMZM2G131266 | B12: GO:0003700GO:0006355 | C12: ap2-like ethylene-responsive transcription factor at1g16060-like | D12: Mo17 0 h | E12: Mo17 6 h | F12: 0.939675 | G12: 13.369 | H12: 3.83059
A13: AC233910.1_FG003 | B13: GO:0003735GO:0006412GO:0006464GO:0005840 | C13: NA | D13: Mo17 0 h | E13: Mo17 6 h | F13: 0.324373 | G13: 4.20873 | H13: 3.69766
A14: GRMZM2G065585 | B14: GO:0016020GO:0005975GO:0004553 | C14: beta glucanase | D14: Mo17 0 h | E14: Mo17 6 h | F14: 4.20212 | G14: 53.8332 | H14: 3.67931
A15: GRMZM2G304121 | B15: NA | C15: eukaryotic translation initiation factor 6 | D15: Mo17 0 h | E15: Mo17 6 h | F15: 0.23059 | G15: 2.76789 | H15: 3.58539
A16: GRMZM2G160515 | B16: NA | C16: NA | D16: Mo17 0 h | E16: Mo17 6 h | F16: 0.928736 | G16: 10.3829 | H16: 3.48279
... A551: GRMZM2G122038 | B551: NA | C551: coatomer subunit beta -3 | D551: Mo17 0 h | E551: Mo17 6 h | F551: 0.508189 | G551: 1.01712 | H551: 1.00106
A552: GRMZM2G380789 | B552: GO:0016021 | C552: heptahelical protein 4 | D552: Mo17 0 h | E552: Mo17 6 h | F552: 0 | G552: 0.772956 | H552: BD
A553: GRMZM2G004106 | B553: GO:0005507GO:0009055 | C553: chemocyanin precursor | D553: Mo17 0 h | E553: Mo17 6 h | F553: 0 | G553: 2.86138 | H553: BD
A554: AC190841.2_FG007 | B554: NA | C554: NA | D554: Mo17 0 h | E554: Mo17 6 h | F554: 0 | G554: 1.41369 | H554: BD
A555: GRMZM2G108847 | B555: GO:0004867 | C555: serine-type endopeptidase inhibitor | D555: Mo17 0 h | E555: Mo17 6 h | F555: 0 | G555: 2.39929 | H555: BD
A556: AC214635.3_FG006 | B556: NA | C556: NA | D556: Mo17 0 h | E556: Mo17 6 h | F556: 0 | G556: 3.48094 | H556: BD
A557: AC187896.3_FG006 | B557: NA | C557: NA | D557: Mo17 0 h | E557: Mo17 6 h | F557: 0 | G557: 1.87524 | H557: BD
A558: GRMZM2G454514 | B558: GO:0050825GO:0042309GO:0050826 | C558: hypothetical protein SORBIDRAFT_09g029320 | D558: Mo17 0 h | E558: Mo17 6 h | F558: 0 | G558: 0.898918 | H558: BD
A559: AC196726.2_FG001 | B559: NA | C559: NA | D559: Mo17 0 h | E559: Mo17 6 h | F559: 0 | G559: 1.50499 | H559: BD

Sheet up-regulated in Mo17 24 h
A1: Table S3. Differentially expressed genes in response to R. padi feeding in B73 and Mo17
A2: Genes up- and down-regulated by R. padi treatment in B73 and Mo17.
A3: Mo17 0 h:No aphid treatment on Mo17, Mo17 24 h: Aphid treatment Mo17 for 24 h; NA：no annotation.BD: numerator or denominator is below of detection
A4: Gene ID | B4: GO term | C4: Description | D4: sample_1 | E4: sample_2 | F4: value_1 | G4: value_2 | H4: log2(fold_change)
A5: GRMZM2G337594 | B5: NA | C5: hypothetical protein | D5: Mo17 0 h | E5: Mo17 24 h | F5: 0.568599 | G5: 5.8463 | H5: 3.36204
A6: GRMZM2G133988 | B6: GO:0008152 | C6: 3-isopropylmalate dehydratase-like | D6: Mo17 0 h | E6: Mo17 24 h | F6: 1.19113 | G6: 9.25129 | H6: 2.95732
A7: GRMZM2G010044 | B7: GO:0008652GO:0016836GO:0051539 | C7: 3-isopropylmalate dehydratase | D7: Mo17 0 h | E7: Mo17 24 h | F7: 6.3386 | G7: 46.3323 | H7: 2.86978
A8: GRMZM2G135385 | B8: GO:0020037 | C8: cytochrome b5 | D8: Mo17 0 h | E8: Mo17 24 h | F8: 0.396047 | G8: 2.83019 | H8: 2.83716
A9: GRMZM2G063880 | B9: GO:0003700GO:0043565GO:0005634GO:0045449 | C9: wrky transcription factor | D9: Mo17 0 h | E9: Mo17 24 h | F9: 0.210979 | G9: 1.38169 | H9: 2.71126
A10: GRMZM2G065585 | B10: GO:0016020GO:0005975GO:0004553 | C10: beta glucanase | D10: Mo17 0 h | E10: Mo17 24 h | F10: 4.20212 | G10: 26.6938 | H10: 2.66732
A11: H4C7 | B11: NA | C11: NA | D11: Mo17 0 h | E11: Mo17 24 h | F11: 19.5368 | G11: 115.267 | H11: 2.56071
A12: GRMZM2G117706 | B12: GO:0020037GO:0005576GO:0004601GO:0006979GO:0009055 | C12: bacterial-induced peroxidase precursor | D12: Mo17 0 h | E12: Mo17 24 h | F12: 0.404387 | G12: 2.37624 | H12: 2.55487
A13: GRMZM2G468111 | B13: NA | C13: uncharacterized protein LOC100277849 | D13: Mo17 0 h | E13: Mo17 24 h | F13: 1.70723 | G13: 9.90091 | H13: 2.5359
A14: GRMZM2G046615 | B14: GO:0016829GO:0000287GO:0008152 | C14: terpene synthase 2 | D14: Mo17 0 h | E14: Mo17 24 h | F14: 1.46049 | G14: 7.87792 | H14: 2.43136
A15: GRMZM2G064406 | B15: GO:0016829GO:0000287GO:0008152 | C15: terpene synthase 2 | D15: Mo17 0 h | E15: Mo17 24 h | F15: 0.309078 | G15: 1.66597 | H15: 2.43032
A16: GRMZM2G071277 | B16: GO:0008270GO:0005515GO:0009055 | C16: ring zinc finger | D16: Mo17 0 h | E16: Mo17 24 h | F16: 0.20066 | G16: 1.07697 | H16: 2.42416
... A76: GRMZM2G119975 | B76: NA | C76: heavy-metal-associated domain-containing protein | D76: Mo17 0 h | E76: Mo17 24 h | F76: 5.50973 | G76: 15.5334 | H76: 1.49532
A77: GRMZM2G127336 | B77: GO:0016829GO:0000287GO:0008152 | C77: #NAME? | D77: Mo17 0 h | E77: Mo17 24 h | F77: 0.500957 | G77: 1.38585 | H77: 1.46801
A78: GRMZM2G010321 | B78: GO:0005960GO:0006546 | C78: glycine decarboxylase complex h-protein | D78: Mo17 0 h | E78: Mo17 24 h | F78: 1.29216 | G78: 3.57035 | H78: 1.46628
A79: GRMZM2G436448 | B79: GO:0004674GO:0006468GO:0004713GO:0005524 | C79: rust resistance kinase lr10 | D79: Mo17 0 h | E79: Mo17 24 h | F79: 2.64149 | G79: 7.29302 | H79: 1.46517
A80: GRMZM2G088819 | B80: GO:0005509 | C80: calcium-binding protein cml42 | D80: Mo17 0 h | E80: Mo17 24 h | F80: 2.07739 | G80: 5.70481 | H80: 1.4574
A81: GRMZM2G001426 | B81: NA | C81: della protein | D81: Mo17 0 h | E81: Mo17 24 h | F81: 0.302088 | G81: 0.828479 | H81: 1.4555
A82: GRMZM5G839644 | B82: NA | C82: protein kinase xa21 | D82: Mo17 0 h | E82: Mo17 24 h | F82: 0.390666 | G82: 1.06982 | H82: 1.45336
A83: GRMZM2G431288 | B83: GO:0004497GO:0020037GO:0009055 | C83: elicitor-inducible cytochrome p450 | D83: Mo17 0 h | E83: Mo17 24 h | F83: 3.39158 | G83: 9.25755 | H83: 1.44867
A84: GRMZM2G126062 | B84: GO:0055114GO:0016491 | C84: aldose reductase | D84: Mo17 0 h | E84: Mo17 24 h | F84: 0.813499 | G84: 2.21771 | H84: 1.44686
A85: GRMZM2G072808 | B85: GO:0048046GO:0005507GO:0046274GO:0008471GO:0055114 | C85: l-ascorbate oxidase precursor | D85: Mo17 0 h | E85: Mo17 24 h | F85: 2.17193 | G85: 5.92083 | H85: 1.44682
A86: GRMZM2G466044 | B86: GO:0003700GO:0006355GO:0050825GO:0042309GO:0050826 | C86: ap2-related transcription factor | D86: Mo17 0 h | E86: Mo17 24 h | F86: 1.97216 | G86: 5.37528 | H86: 1.44656
A87: YS1 | B87: NA | C87: NA | D87: Mo17 0 h | E87: Mo17 24 h | F87: 1.20398 | G87: 3.26974 | H87: 1.44136
A88: GRMZM2G020054 | B88: GO:0003700GO:0006355 | C88: ethylene-responsive transcription factor 4 | D88: Mo17 0 h | E88: Mo17 24 h | F88: 0.725604 | G88: 1.94914 | H88: 1.42558
A89: GRMZM2G125850 | B89: GO:0005215GO:0016021GO:0006810GO:0050825GO:0042309GO:0050826 | C89: glucose-6-phosphate translocator | D89: Mo17 0 h | E89: Mo17 24 h | F89: 1.15072 | G89: 3.05165 | H89: 1.40705
... A214: GRMZM2G145374 | B214: GO:0008270GO:0005515 | C214: ring u-box domain-containing protein | D214: Mo17 0 h | E214: Mo17 24 h | F214: 0.526619 | G214: 1.05491 | H214: 1.00228
A215: GRMZM2G108847 | B215: GO:0004867 | C215: serine-type endopeptidase inhibitor | D215: Mo17 0 h | E215: Mo17 24 h | F215: 0 | G215: 2.09213 | H215: BD
A216: AC214635.3_FG006 | B216: NA | C216: NA | D216: Mo17 0 h | E216: Mo17 24 h | F216: 0 | G216: 3.45485 | H216: BD
A217: AC203048.3_FG001 | B217: NA | C217: NA | D217: Mo17 0 h | E217: Mo17 24 h | F217: 0 | G217: 1.5045 | H217: BD
A218: AC196726.2_FG001 | B218: NA | C218: NA | D218: Mo17 0 h | E218: Mo17 24 h | F218: 0 | G218: 1.30398 | H218: BD
A219: GRMZM5G813809 | B219: NA | C219: NA | D219: Mo17 0 h | E219: Mo17 24 h | F219: 0 | G219: 1.93781 | H219: BD

Sheet down-regulated in B73 6h
A1: Table S3. Differentially expressed genes in response to R. padi feeding in B73 and Mo17
A2: Genes up- and down-regulated by R. padi treatment in B73 and Mo17.
A3: B73 0 h:No aphid treatment on B73,B73 6 h: Aphid treatment B73 for 6 h; NA：no annotation.BD: numerator or denominator is below of detection
A4: gene | B4: GO term | C4: Description | D4: sample_1 | E4: sample_2 | F4: value_1 | G4: value_2 | H4: log2(fold_change)
A5: GRMZM2G305526 | B5: GO:0048046GO:0005507GO:0046274GO:0008471GO:0055114 | C5: lac10_orysj ame: full=laccase-10 ame: full=benzenediol:oxygen oxidoreductase 10 ame: full=diphenol oxidase 10 ame: full=urishiol oxidase 10 flags: precursor | D5: B73 0 h | E5: B73 6 h | F5: 2.85736 | G5: 0.173362 | H5: -4.04282
A6: GRMZM2G005633 | B6: GO:0016491GO:0004568GO:0006032GO:0008061GO:0016998 | C6: chitinase | D6: B73 0 h | E6: B73 6 h | F6: 2.37799 | G6: 0.211772 | H6: -3.48916
A7: GRMZM2G090245 | B7: NA | C7: adenosine diphosphate glucose pyrophosphatase | D7: B73 0 h | E7: B73 6 h | F7: 117.569 | G7: 14.2035 | H7: -3.04919
A8: GRMZM2G477063 | B8: NA | C8: unknown | D8: B73 0 h | E8: B73 6 h | F8: 1.48085 | G8: 0.190247 | H8: -2.96047
A9: GRMZM2G381441 | B9: GO:0003700GO:0006355 | C9: ethylene-responsive transcription factor | D9: B73 0 h | E9: B73 6 h | F9: 2.34788 | G9: 0.333399 | H9: -2.81603
A10: GRMZM2G100412 | B10: GO:0004497GO:0020037GO:0009055 | C10: cytochrome p450 87a3-like | D10: B73 0 h | E10: B73 6 h | F10: 7.99816 | G10: 1.15232 | H10: -2.79513
A11: GRMZM2G176347 | B11: GO:0050825GO:0042309GO:0050826 | C11: lipid binding protein precursor | D11: B73 0 h | E11: B73 6 h | F11: 1.79139 | G11: 0.274833 | H11: -2.70445
A12: GRMZM2G108597 | B12: NA | C12: amino acid transporter | D12: B73 0 h | E12: B73 6 h | F12: 0.924113 | G12: 0.144967 | H12: -2.67234
A13: TPS10 | B13: NA | C13: NA | D13: B73 0 h | E13: B73 6 h | F13: 3.17993 | G13: 0.509448 | H13: -2.64199
A14: GRMZM2G118172 | B14: GO:0050825GO:0042309GO:0050826 | C14: vq motif family protein | D14: B73 0 h | E14: B73 6 h | F14: 29.6285 | G14: 4.81047 | H14: -2.62274
A15: GRMZM2G095280 | B15: GO:0016758GO:0008152 | C15: indole-3-acetate beta-glucosyltransferase | D15: B73 0 h | E15: B73 6 h | F15: 7.73624 | G15: 1.27054 | H15: -2.60619
A16: GRMZM2G146913 | B16: GO:0005737GO:0004364GO:0008152 | C16: glutathione s-transferase gstu6 | D16: B73 0 h | E16: B73 6 h | F16: 2.69139 | G16: 0.443651 | H16: -2.60085
... A428: GRMZM2G161310 | B428: GO:0015904GO:0016021GO:0015520GO:0046677 | C428: probable peptide nitrate transporter at3g43790-like | D428: B73 0 h | E428: B73 6 h | F428: 22.781 | G428: 11.3866 | H428: -1.00049
A429: GRMZM2G336859 | B429: NA | C429: NA | D429: B73 0 h | E429: B73 6 h | F429: 0.881977 | G429: 0 | H429: BD
A430: GRMZM2G332423 | B430: GO:0005506GO:0016491 | C430: acc oxidase | D430: B73 0 h | E430: B73 6 h | F430: 0.915181 | G430: 0 | H430: BD
A431: GRMZM2G132880 | B431: NA | C431: terminal flower 1 | D431: B73 0 h | E431: B73 6 h | F431: 3.94234 | G431: 0 | H431: BD

Sheet down-regulated in B73 24 h
A1: Table S3. Differentially expressed genes in response to R. padi feeding in B73 and Mo17
A2: Genes up- and down-regulated by R. padi treatment in B73 and Mo17.
A3: B73 0 h:No aphid treatment on B73,B73 24 h: Aphid treatment B73 for 24 h; NA：no annotation.BD: numerator or denominator is below of detection
A4: gene | B4: GO term | C4: Description | D4: sample_1 | E4: sample_2 | F4: value_1 | G4: value_2 | H4: log2(fold_change)
A5: GRMZM2G074743 | B5: GO:0005740GO:0007585 | C5: alternative oxidase | D5: B73 0 h | E5: B73 24 h | F5: 3.66699 | G5: 0.146102 | H5: -4.64955
